#VRML_SIM R2025a utf8

EXTERNPROTO "https://raw.githubusercontent.com/cyberbotics/webots/develop/projects/objects/backgrounds/protos/TexturedBackground.proto"
EXTERNPROTO "https://raw.githubusercontent.com/cyberbotics/webots/develop/projects/objects/plants/protos/PottedTree.proto"
EXTERNPROTO "https://raw.githubusercontent.com/cyberbotics/webots/develop/projects/objects/floors/protos/Floor.proto"
EXTERNPROTO "https://raw.githubusercontent.com/cyberbotics/webots/develop/projects/appearances/protos/CementTiles.proto"
EXTERNPROTO "https://raw.githubusercontent.com/cyberbotics/webots/develop/projects/objects/apartment_structure/protos/Window.proto"
EXTERNPROTO "https://raw.githubusercontent.com/cyberbotics/webots/develop/projects/objects/apartment_structure/protos/Wall.proto"
EXTERNPROTO "https://raw.githubusercontent.com/cyberbotics/webots/develop/projects/appearances/protos/Roughcast.proto"
EXTERNPROTO "https://raw.githubusercontent.com/cyberbotics/webots/develop/projects/objects/apartment_structure/protos/Radiator.proto"
EXTERNPROTO "https://raw.githubusercontent.com/cyberbotics/webots/develop/projects/objects/apartment_structure/protos/Door.proto"
EXTERNPROTO "https://raw.githubusercontent.com/cyberbotics/webots/develop/projects/objects/cabinet/protos/Cabinet.proto"
EXTERNPROTO "https://raw.githubusercontent.com/cyberbotics/webots/develop/projects/objects/factory/containers/protos/CardboardBox.proto"
EXTERNPROTO "https://raw.githubusercontent.com/cyberbotics/webots/develop/projects/objects/kitchen/fridge/protos/Fridge.proto"
EXTERNPROTO "https://raw.githubusercontent.com/cyberbotics/webots/develop/projects/objects/lights/protos/FloorLight.proto"
EXTERNPROTO "https://raw.githubusercontent.com/cyberbotics/webots/develop/projects/objects/living_room_furniture/protos/Sofa.proto"
EXTERNPROTO "https://raw.githubusercontent.com/cyberbotics/webots/develop/projects/objects/living_room_furniture/protos/Armchair.proto"
EXTERNPROTO "https://raw.githubusercontent.com/cyberbotics/webots/develop/projects/objects/paintings/protos/LandscapePainting.proto"
EXTERNPROTO "https://raw.githubusercontent.com/cyberbotics/webots/develop/projects/objects/tables/protos/Table.proto"
EXTERNPROTO "https://raw.githubusercontent.com/cyberbotics/webots/develop/projects/objects/traffic/protos/DirectionPanel.proto"
EXTERNPROTO "https://raw.githubusercontent.com/cyberbotics/webots/develop/projects/objects/plants/protos/BunchOfSunFlowers.proto"
EXTERNPROTO "https://raw.githubusercontent.com/cyberbotics/webots/develop/projects/devices/robotis/protos/RobotisLds01.proto"
EXTERNPROTO "https://raw.githubusercontent.com/cyberbotics/webots/R2025a/projects/appearances/protos/BrushedAluminium.proto"
EXTERNPROTO "https://raw.githubusercontent.com/cyberbotics/webots/develop/projects/appearances/protos/TireRubber.proto"
EXTERNPROTO "https://raw.githubusercontent.com/cyberbotics/webots/develop/projects/appearances/protos/Pcb.proto"
EXTERNPROTO "https://raw.githubusercontent.com/cyberbotics/webots/develop/projects/appearances/protos/RoughPolymer.proto"
EXTERNPROTO "https://raw.githubusercontent.com/cyberbotics/webots/develop/projects/appearances/protos/MattePaint.proto"
EXTERNPROTO "https://raw.githubusercontent.com/cyberbotics/webots/R2025a/projects/appearances/protos/Copper.proto"

WorldInfo {
  info [
    "Simple TurtleBot3 Burger simulation that can be controlled by a ROS."
  ]
  title "ROS2 simulation of the TurtleBot3 Burger robot"
  basicTimeStep 20
}
Viewpoint {
  orientation 0.03374015327249081 -0.9969699788347801 -0.07008896745798956 5.093705569080534
  position 3.9547462969741902 -0.6285517327754151 8.263870860797732
}
TexturedBackground {
  texture "empty_office"
  skybox FALSE
}
DEF anchorA Pose {
  translation 8.35 -3.73 0
  children [
    Shape {
      appearance BrushedAluminium {
      }
      geometry Capsule {
        height 0.1
        radius 0.05
      }
    }
  ]
}
DEF anchorB Pose {
  translation 6.31 -1.8 0
  children [
    Shape {
      appearance BrushedAluminium {
      }
      geometry Capsule {
        height 0.1
        radius 0.05
      }
    }
  ]
}
DEF anchorC Pose {
  translation 9.08 1.97 0
  children [
    Shape {
      appearance BrushedAluminium {
      }
      geometry Capsule {
        height 0.1
        radius 0.05
      }
    }
  ]
}
DEF anchorD Pose {
  translation 6.25 2.83 0
  children [
    Shape {
      appearance BrushedAluminium {
      }
      geometry Capsule {
        height 0.1
        radius 0.05
      }
    }
  ]
}
Robot {
  translation 6.36000000087475 -5.16236907686712e-10 -0.00015506328274712822
  rotation -0.002119255150314241 -0.9999977543722822 2.8285120496933486e-06 0.002891560279428233
  children [
    Pose {
      translation -0.03 0 0.153
      children [
        Solid {
          name "imu_link"
        }
        GPS {
        }
        InertialUnit {
          name "inertial_unit"
        }
        RobotisLds01 {
        }
      ]
    }
    DEF uwb_back Transform {
      translation -0.15 0 0.05
      scale 0.3 0.3 0.3
      children [
        Shape {
          appearance Copper {
          }
          geometry Box {
            size 0.1 0.1 0.1
          }
        }
      ]
    }
    DEF uwb_left Transform {
      translation 0 0.15 0.05
      scale 0.3 0.3 0.3
      children [
        Shape {
          appearance Copper {
          }
          geometry Box {
            size 0.1 0.1 0.1
          }
        }
      ]
    }
    DEF uwb_right Transform {
      translation 0 -0.15 0.05
      scale 0.3 0.3 0.3
      children [
        Shape {
          appearance Copper {
          }
          geometry Box {
            size 0.1 0.1 0.1
          }
        }
      ]
    }
    DEF RIGHT_JOINT HingeJoint {
      jointParameters HingeJointParameters {
        position -1.1893409326652389e-11
        axis 0 1 0
        anchor 0 -0.08 0.033
      }
      device [
        RotationalMotor {
          name "right wheel motor"
          consumptionFactor -0.001
          maxVelocity 6.67
        }
        PositionSensor {
          name "right wheel sensor"
          resolution 0.00628
        }
      ]
      endPoint Solid {
        translation 0 -0.08 0.033
        rotation 0 -1 0 1.5707960017840172
        children [
          DEF RIGHT_WHEEL Pose {
            rotation 1 0 0 -1.5708003061004252
            children [
              DEF WHEEL_SHAPE Group {
                children [
                  Shape {
                    appearance PBRAppearance {
                      baseColor 0 0 0
                      roughness 1
                      metalness 0
                    }
                    geometry Mesh {
                      url [
                        "https://raw.githubusercontent.com/cyberbotics/webots/develop/projects/robots/robotis/turtlebot/protos/meshes/wheel_shape.obj"
                      ]
                    }
                  }
                  Shape {
                    appearance PBRAppearance {
                      baseColor 0 0 0
                      roughness 1
                      metalness 0
                    }
                    geometry Mesh {
                      url [
                        "https://raw.githubusercontent.com/cyberbotics/webots/develop/projects/robots/robotis/turtlebot/protos/meshes/inner_wheel.obj"
                      ]
                    }
                  }
                  Shape {
                    appearance TireRubber {
                      textureTransform TextureTransform {
                        scale 1.7 0.76
                        translation 0 0.164
                      }
                      type "bike"
                    }
                    geometry Mesh {
                      url [
                        "https://raw.githubusercontent.com/cyberbotics/webots/develop/projects/robots/robotis/turtlebot/protos/meshes/tire.obj"
                      ]
                    }
                  }
                  Shape {
                    appearance PBRAppearance {
                    }
                    geometry Mesh {
                      url [
                        "https://raw.githubusercontent.com/cyberbotics/webots/develop/projects/robots/robotis/turtlebot/protos/meshes/wheel_support.obj"
                      ]
                    }
                  }
                ]
              }
            ]
          }
        ]
        name "right wheel"
        boundingObject Pose {
          rotation 1 0 0 -1.570796
          children [
            Cylinder {
              height 0.018
              radius 0.033
            }
          ]
        }
        physics Physics {
          density -1
          mass 0.028499
          centerOfMass [
            0 0 0
          ]
        }
      }
    }
    DEF LEFT_JOINT HingeJoint {
      jointParameters HingeJointParameters {
        position 8.618927587182217e-12
        axis 0 1 0
        anchor 0 0.08 0.033
      }
      device [
        RotationalMotor {
          name "left wheel motor"
          consumptionFactor -0.001
          maxVelocity 6.67
        }
        PositionSensor {
          name "left wheel sensor"
          resolution 0.00628
        }
      ]
      endPoint Solid {
        translation 0 0.08 0.033
        rotation -0.7071047816414237 1.5170074177773081e-15 -0.7071087807260172 3.141588
        children [
          DEF RIGHT_WHEEL Pose {
            rotation 1 0 0 -1.5708003061004252
            children [
              USE WHEEL_SHAPE
            ]
          }
        ]
        name "left wheel"
        boundingObject Pose {
          rotation 1 0 0 -1.570796
          children [
            Cylinder {
              height 0.018
              radius 0.033
            }
          ]
        }
        physics Physics {
          density -1
          mass 0.028499
          centerOfMass [
            0 0 0
          ]
        }
      }
    }
    DEF CASTER_JOINT BallJoint {
      jointParameters BallJointParameters {
        position 4.7397790380276285e-07
        anchor -0.081 0 0.004
      }
      endPoint Solid {
        translation -0.081 0 0.004
        rotation 0.005584031351214733 0.9999832594549015 -0.0015163785212399061 8.488002259905494e-05
        children [
          Shape {
            appearance PBRAppearance {
            }
            geometry DEF CASTER_SPHERE Sphere {
              radius 0.004
              subdivision 2
            }
          }
        ]
        boundingObject USE CASTER_SPHERE
        physics Physics {
        }
      }
    }
    DEF BODY Pose {
      translation 0 0 0.01
      children [
        DEF MOTORS Shape {
          appearance PBRAppearance {
            baseColor 0 0 0
            roughness 0.8
            metalness 0
          }
          geometry Mesh {
            url [
              "https://raw.githubusercontent.com/cyberbotics/webots/develop/projects/robots/robotis/turtlebot/protos/meshes/motors.obj"
            ]
          }
        }
        DEF CARDS Shape {
          appearance Pcb {
          }
          geometry Mesh {
            url [
              "https://raw.githubusercontent.com/cyberbotics/webots/develop/projects/robots/robotis/turtlebot/protos/meshes/cards.obj"
            ]
          }
        }
        DEF HOLDERS Shape {
          appearance DEF MAIN_APP RoughPolymer {
            baseColor 0 0 0
            textureTransform TextureTransform {
              scale 3 3
            }
          }
          geometry Mesh {
            url [
              "https://raw.githubusercontent.com/cyberbotics/webots/develop/projects/robots/robotis/turtlebot/protos/meshes/holders.obj"
            ]
          }
        }
        DEF BODY_FLOOR_0 Shape {
          appearance USE MAIN_APP
          geometry Mesh {
            url [
              "https://raw.githubusercontent.com/cyberbotics/webots/develop/projects/robots/robotis/turtlebot/protos/meshes/body_floor.obj"
            ]
          }
        }
        DEF BODY_FLOOR_1 Pose {
          translation 0 0 0.0376
          children [
            USE BODY_FLOOR_0
          ]
        }
        DEF BODY_FLOOR_2 Pose {
          translation 0 0 0.085
          children [
            USE BODY_FLOOR_0
          ]
        }
        DEF BODY_FLOOR_3 Pose {
          translation 0 0 0.1325
          children [
            USE BODY_FLOOR_0
          ]
        }
        DEF BATTERY Shape {
          appearance MattePaint {
            baseColor 0.054902 0.121569 0.356863
          }
          geometry Mesh {
            url [
              "https://raw.githubusercontent.com/cyberbotics/webots/develop/projects/robots/robotis/turtlebot/protos/meshes/battery.obj"
            ]
          }
        }
        DEF SCREWS Shape {
          appearance PBRAppearance {
          }
          geometry Mesh {
            url [
              "https://raw.githubusercontent.com/cyberbotics/webots/develop/projects/robots/robotis/turtlebot/protos/meshes/screws.obj"
            ]
          }
        }
        DEF BARS Shape {
          appearance BrushedAluminium {
            textureTransform TextureTransform {
              scale 3 2
            }
          }
          geometry Mesh {
            url [
              "https://raw.githubusercontent.com/cyberbotics/webots/develop/projects/robots/robotis/turtlebot/protos/meshes/bars.obj"
            ]
          }
        }
      ]
    }
    Accelerometer {
      translation -0.032 0 0.078
    }
    Gyro {
      translation -0.032 0 0.078
    }
    Compass {
      translation -0.032 0 0.078
    }
  ]
  name "TurtleBot3Burger"
  boundingObject Group {
    children [
      Pose {
        translation -0.032 0 0.08
        children [
          Box {
            size 0.097 0.137 0.1425
          }
        ]
      }
      Pose {
        translation -0.032 0 0.08
        children [
          Box {
            size 0.135 0.095 0.143
          }
        ]
      }
    ]
  }
  physics Physics {
    density -1
    mass 0.825735
    centerOfMass [
      -0.035 0 0.03
    ]
  }
  controller "uwb_steer_controller"
  controllerArgs [
    ""
  ]
  supervisor TRUE
}
PottedTree {
  translation 7.38 -1.95 0
  rotation 0 0 1 1.5708
  name "potted tree(5)"
}
PottedTree {
  translation 5.8 3.3 0
  rotation 0 0 1 1.5708
  name "potted tree(8)"
}
Floor {
  translation 7.5 0 0
  name "floor(1)"
  size 5 10
  tileSize 2 2
  appearance CementTiles {
    textureTransform TextureTransform {
      scale 0.6 0.6
    }
  }
}
Window {
  translation 6.5 -5.1 0
  rotation 0 0 1 -1.5707953071795862
  name "window(1)"
  size 0.2 1 2.4
}
Wall {
  translation 7.5 5.1 0
  rotation 0 0 1 3.14159
  name "wall(5)"
  size 5 0.2 2.4
  appearance Roughcast {
    textureTransform TextureTransform {
      scale 7 2.4
    }
  }
}
Wall {
  translation 5.5 -5.1 0
  name "wall(7)"
  size 1 0.2 2.4
  appearance Roughcast {
    textureTransform TextureTransform {
      scale 7 2.4
    }
  }
}
Wall {
  translation 8.5 -5.1 0
  name "wall(10)"
  size 3 0.2 2.4
  appearance Roughcast {
    textureTransform TextureTransform {
      scale 7 2.4
    }
  }
}
Wall {
  translation 10.1 0 0
  rotation -0.00022772198819084869 0 0.9999999740713477 1.57103
  name "wall(6)"
  size 10.4 0.2 2.4
  appearance Roughcast {
    textureTransform TextureTransform {
      scale 7 2.4
    }
  }
}
Wall {
  translation 5 2 0
  rotation 0 0.00022681898833087582 0.9999999742765728 -1.570565307179586
  name "wall(2)"
  size 6 0.2 2.4
  appearance Roughcast {
    textureTransform TextureTransform {
      scale 7 2.4
    }
  }
}
Wall {
  translation 5 -3.5 0
  rotation 0 0.0002268199883307215 0.9999999742763461 -1.570565307179586
  name "wall(1)"
  size 3 0.2 2.4
  appearance Roughcast {
    textureTransform TextureTransform {
      scale 7 2.4
    }
  }
}
Radiator {
  translation 7.33 4.87 0.38
  rotation 0.0002336949872371335 0 0.9999999726933261 -1.5710253071795863
}
Door {
  translation 5 -1.5 0
  rotation -0.581329088895979 0.5726190875640585 -0.5780690883974646 0.000396075
  position -1.5009885914042251
  wallAppearance Roughcast {
    textureTransform TextureTransform {
      scale 7 2.4
    }
  }
  frameAppearance Roughcast {
    textureTransform TextureTransform {
      scale 1 2.4
    }
  }
}
Cabinet {
  translation 9.5 -2.5 0
  rotation 0.00011300299708654554 0.00011407199705898447 0.999999987108951 3.14137
}
CardboardBox {
  translation 9.7 4.7 0.3
  rotation -0.577349935856137 0.577349935856137 0.5773509358560258 2.09439
}
CardboardBox {
  translation 9 4.6 0.3
  rotation 0.06500310682387538 0.06496520681989673 -0.995768104533426 -1.5750353071795864
  name "cardboard box(1)"
}
CardboardBox {
  translation 9.6 4 0.3
  rotation -0.06496610766674145 -0.06500200767097807 -0.9957681175119917 -1.5750353071795864
  name "cardboard box(2)"
}
CardboardBox {
  translation 9.4 4.5 0.9
  rotation -0.06512832729035975 -0.027078811346683294 -0.997509417980808 -2.358005307179586
  name "cardboard box(3)"
}
Fridge {
  translation 5.7 4.64 0
  rotation 0.5822796992968663 -0.5748877031142695 0.5748517031328608 -0.0003953071795859131
}
FloorLight {
  translation 9.3 1 0
  name "floor light(1)"
  bulbColor 0.26331 0.374105 0.963333
  pointLightColor 0.0350805 0.179232 0.956664
  pointLightIntensity 4
  pointLightCastShadows TRUE
}
Sofa {
  translation 9 -0.518 0
  rotation 0.00014495699695408652 0 0.9999999894937345 3.14131
}
Armchair {
  translation 7.59 1.03026 6.83374e-06
  rotation 0.00022763298820402747 0 0.999999974091611 -1.5710253071795863
}
Armchair {
  translation 7.28 1.03025 7.7395e-05
  rotation 0.00022763298820402747 0 0.999999974091611 -1.5710253071795863
  name "armchair(1)"
}
LandscapePainting {
  translation 8.5 -4.98 1.2
  rotation -0.00014498499390527302 -0.00014496999390590354 -0.9999999789815259 -1.570515307179586
}
PottedTree {
  translation 9.17 -1.7 0
  rotation 0 0 1 1.5708
}
PottedTree {
  translation 5.6 -4.5 0
  rotation 0 0 1 1.5708
  name "potted tree(3)"
}
Table {
  translation 7.7 -0.52 0
  rotation 0 0.00022690898831680196 0.9999999742561552 -1.570565307179586
  size 1.3 0.8 0.5
}
DirectionPanel {
  translation 8 5 1.5
  rotation 0.00010265399783649644 -0.00010265399783649644 0.9999999894621566 1.5708
}
BunchOfSunFlowers {
  translation 7.68 -0.52 0.5
  rotation 0 0 1 1.5708
}
